Workbook

Sheet Scénarios
A1: Identification générale
A2: Élément | B2: Contenu à renseigner
A3: Nom du projet | B3: Méga-barrage hydroélectrique sur le Yarlung Tsangpo
A4: Localisation | B4: Tibet (Chine), fleuve Yarlung Tsangpo (Brahmapoutre amont)
A5: Type d’investissement | B5: Infrastructure hydraulique et énergétique
A6: Objectif principal | B6: Production d’électricité + régulation hydrologique
A7: Décideur | B7: État chinois
A9: Scénario de référence
A10: Élément | B10: Situation sans projet | C10: Situation avec projet | D10: Variation attendue
A11: Production énergétique | B11: Maintien mix actuel | C11: Forte augmentation hydro | D11: TWh +
A12: Gestion des crues | B12: Régulation limitée | C12: Amélioration partielle | D12: Dommages -
A13: Émissions CO2 | B13: Élevées | C13: Réduction relative | D13: Tonnes CO2 -
A14: Développement | B14: Croissance stable | C14: Expansion régionale | D14: PIB local +
A15: Biodiversité | B15: État naturel | C15: Perturbation | D15: Services écosystémiques -
A16: Déplacements | B16: Non | C16: Oui | D16: Bien-être ménages -
A17: Stress hydrique | B17: Non maîtrisé | C17: Régulation partielle | D17: Variabilité débit -
A18: Débit vers Inde/Bangladesh | B18: Naturel | C18: Régulé par Chine | D18: idk, politique ?
A19: Production agricole aval | B19: Dépend du régime naturel | C19: Risque modification saisonnalité | D19: idk, probablement rendement -
A20: Sécurité eau aval | B20: Dépend climat | C20: Dépend gestion chinoise | D20: dépendance stratégique +

Sheet Impacts
A1: Identification des impacts
A2: Catégorie | B2: Impact | C2: Acteurs concernés | D2: Sens | E2: Quantifiable ? | F2: Source à chercher | G2: Commentaire
A3: Social | B3: Déplacements population | C3: Population locale | D3: - | E3: Oui | F3: Three Gorges | G3: relocalisation forcée
A4: Social | B4: Développement régional | C4: Région Tibet | D4: + | E4: Partiel | F4: études barrages | G4: effet multiplicateur
A5: Hydrologie | B5: Régulation crues | C5: Population aval | D5: + | E5: Partiel | F5: données inondations | G5: réduction dommages
A6: Hydrologie | B6: Modification débit saisonnier | C6: Inde / Bangladesh | D6: idk | E6: Difficile | F6: études fleuves transfrontaliers | G6: dépend gestion barrage
A7: Géopolitique | B7: Tensions hydriques régionales | C7: Inde / Bangladesh / Chine | D7: - | E7: Non | F7: analyses géopolitiques | G7: externalité politique
A8: Environnement | B8: Perturbation biodiversité fluviale | C8: Écosystèmes locaux | D8: - | E8: Difficile | F8: études écologiques | G8: fragmentation habitats
A9: Environnement | B9: Modification transport sédiments | C9: Agriculture aval | D9: - | E9: Partiel | F9: hydrologie fleuves | G9: impact sols aval
A10: Énergie | B10: Production hydroélectrique supplémentaire | C10: Chine (ménages, industrie) | D10: + | E10: Oui | F10: capacité barrage, TWh | G10: Bénéfice principal
A11: Énergie | B11: Réduction production charbon | C11: Chine | D11: + | E11: Oui | F11: mix énergétique | G11: substitution énergétique
A12: Économie | B12: Coût construction barrage | C12: État chinois | D12: - | E12: Oui | F12: coût projet | G12: investissement initial
A13: Économie | B13: Coût maintenance infrastructure | C13: État chinois | D13: - | E13: Oui | F13: barrages comparables | G13: coût annuel
... A17: Climat | B17: Réduction émissions CO2 | C17: Monde | D17: + | E17: Oui | F17: facteur émissions charbon | G17: bénéfice climatique global

Sheet Valorisation
A1: Méthodes de valorisation
A2: Impact | B2: Type | C2: Méthode de valorisation | D2: Données nécessaires | E2: Unité | F2: Source
A3: =Impacts!$B3 -> Déplacements population | B3: Coût social | C3: Coût de relocalisation + compensation par ménage | D3: Nombre de personnes déplacées, coût moyen de relocalisation | E3: € | F3: Études du barrage des Trois-Gorges | G3: Y
A4: =Impacts!$B4 -> Développement régional | B4: Bénéfice économique | C4: Effet multiplicateur investissement / augmentation PIB régional | D4: Investissement total, multiplicateur régional | E4: € / an | F4: Littérature barrages / développement régional | G4: N
A5: =Impacts!$B5 -> Régulation crues | B5: Bénéfice | C5: Dommages d’inondations évités | D5: Coûts historiques des inondations, fréquence des crues | E5: € / an | F5: Bases catastrophes naturelles | G5: N
A6: =Impacts!$B6 -> Modification débit saisonnier | B6: Impact mixte | C6: Variation production agricole aval | D6: Débits fleuve, rendement agricole, surfaces cultivées | E6: € / an | F6: Études hydrologiques Brahmapoutre | G6: N
A7: =Impacts!$B7 -> Tensions hydriques régionales | B7: Coût potentiel | C7: Analyse qualitative ou proxy coûts diplomatiques / économiques | D7: Indicateurs tensions eau transfrontalières | E7: qualitatif | F7: Études géopolitiques de l’eau | G7: N
A8: =Impacts!$B8 -> Perturbation biodiversité fluviale | B8: Coût environnemental | C8: Valeur des services écosystémiques perdus | D8: Valeur écosystèmes fluviaux / ha | E8: € / an | F8: Études services écosystémiques | G8: N
A9: =Impacts!$B9 -> Modification transport sédiments | B9: Coût économique | C9: Impact sur fertilité sols / agriculture aval | D9: Quantité sédiments, rendement agricole | E9: € / an | F9: Études hydrologie fleuves | G9: N
A10: =Impacts!$B10 -> Production hydroélectrique supplémentaire | B10: Bénéfice | C10: Prix électricité × production hydro | D10: Production annuelle (TWh), prix électricité | E10: € / an | F10: International Energy Agency | G10: Y
A11: =Impacts!$B11 -> Réduction production charbon | B11: Bénéfice climatique | C11: Émissions charbon évitées × prix carbone | D11: Facteur CO2charbon, production substituée | E11: € / an | F11: International Energy Agency | G11: Y
A12: =Impacts!$B12 -> Coût construction barrage | B12: Coût investissement | C12: Coût total du projet | D12: Coût construction estimé | E12: € | F12: Rapports infrastructures | G12: Y
A13: =Impacts!$B13 -> Coût maintenance infrastructure | B13: Coût | C13: % du coût initial par an | D13: Coût barrage initial | E13: € / an | F13: Littérature hydropower | G13: Y
A14: =Impacts!$B14 -> Création emplois construction | B14: Bénéfice social | C14: Salaire moyen × emplois créés | D14: Nombre emplois, salaire moyen | E14: € / an | F14: Projets comparables | G14: A
... A17: =Impacts!$B17 -> Réduction émissions CO2 | B17: Bénéfice global | C17: Tonnes CO2évitées × valeur carbone | D17: tCO2évitées, prix carbone | E17: € / an | F17: IPCC / politiques carbone | G17: Y

Sheet Flux économiques
A1: Tableau des paramètres d'entrée et données manquantes
A2: PARAMÈTRES CLÉS | B2: Valeur centrale | C2: Unité | D2: Commentaire | E2: Source | F2: Colonne1 | G2: Colonne2 | H2: Colonne3
A3: Coût construction CAPEX | B3: 137000 | C3: M$ | E3: RFA/Wikipedia/yale | F3: https://www.rfa.org/english/tibet/2024/12/27/tibet-china-approves-mega-dam-construction/ | G3: https://en.wikipedia.org/wiki/Medog_Hydropower_Station | H3: https://e360.yale.edu/features/china-tibet-yarlung-tsangpo-dam-india-water
A4: Durée de vie projet | B4: 50 | C4: ans | E4: Standard hydroélectrique | F4: https://unu.edu/press-release/ageing-dams-pose-growing-threat
A5: Taux d'actualisation | B5: 0.045 | C5: % | E5: Référence Quinet (France, approche académique) | F5: Quinet, A. (2013), L'évaluation socioéconomique des investissements publics, Commissariat Général à la Stratégie et à la Prospective
A6: Production annuelle | B6: 300 | C6: Twh/an | D6: capacité annoncée, non mesurée | E6: RFA/Wikipedia/yale | F6: https://www.rfa.org/english/tibet/2024/12/27/tibet-china-approves-mega-dam-construction/ | G6: https://en.wikipedia.org/wiki/Medog_Hydropower_Station | H6: https://e360.yale.edu/features/china-tibet-yarlung-tsangpo-dam-india-water
A7: Prix électricité (industrie Chine) | B7: =0.66*0.145 -> 0.0957 | C7: $/kwh | D7: 0,66 CNY/kWh * 0,145 | E7: Intratec, 2025 | F7: https://www.intratec.us/solutions/energy-prices-markets/commodity/electricity-price-china
A8: Facteur CO2charbon substitué | B8: 820 | C8: gCO2/kwh | E8: IEA / Ember | F8: IPCC (2014), Climate Change 2014: Mitigation of Climate Change, Annex III, Table A.III.2, p. 1335. Accessible via : https://www.ipcc.ch/report/ar5/wg3/
A9: Prix carbone ETS Chine | B9: 10 | C9: $/tCO2 | D9: prix très bas comparé à l'EU ETS (70-80 €/t) pas prix du marché mais projection | E9: China-Briefing, nov.2024 | F9: https://www.china-briefing.com/news/china-carbon-trading-emissions-cap/
A10: Ménages déplacés | B10: =15000/3.19 -> 4702.1944 | C10: M"nage | D10: 15000pop/3,19 personnes/ménage | E10: CEIC Data/Wikipedia | F10: https://www.ceicdata.com/en/china/population-no-of-person-per-household/population-average-household-size-tibet | G10: https://en.wikipedia.org/wiki/M%C3%AAdog_County
A11: Coût relocalisation/ménage | B11: =9645*111.18*0.145 -> 155488.01 | C11: $ | D11: 9 645,872 au m2 * 111,18 * 0,145 | E11: CEIC Data/EqualOcean | G11: https://www.ceicdata.com/en/china/nbs-property-price-monthly/property-price-ytd-avg-tibet | H11: https://equalocean.com/briefing/20220628230147939
A12: Dommages crues annuels | B12: 0 | D12: barrage au fil de l'eau sans réservoir significatif, capacité de régulation des crues négligeable
A13: Maintenance annuelle (% CAPEX) | B13: 0.025 | C13: % | F13: IRENA (2012), Cost Analysis of Hydropower, Working Paper, Volume 1: Power Sector, Issue 3/5, International Renewable Energy Agency, Abu Dhabi, p. 24.
A14: Valeurs services écosystémiques | B14: 0 | D14: Non monétisé. Projet run-of-river sans réservoir significatif documenté. Surface impactée non disponible en l'absence d'EIE publique. Valeur de référence disponible : 4 267 Int$/ha/an (de Groot et al., 2012, Rivers and Lakes biome). Impact qualitatif documenté : 79,57% du comté de Medog classé zone écologique extrêmement importante (Duan et al., 2022) | H14: Table 3, p.55, de Groot et al., 2012, Ecosystem Services, vol.1
A16: Flux socio-économiques du projet
A17: FLUX ANNUELS (M€/an) | B17: Valeur calculée | C17: Type | D17: Commentaire
A18: (+) Recettes vente électricité | B18: =B6*1000000000*B7/1000000 -> 28710 | C18: +
A19: (+) Valorisation CO2évité (ETS) | B19: =B6*1000000000*B8/1000000/1000000*B9 -> 2460 | C19: +
A20: (+) Dommages crues évités | B20: =B12 -> 0 | C20: +
A21: (-) Maintenance annuelle | B21: =-B3*B13 -> -3425 | C21: -
A22: (-) Relocalisation | B22: =-(B10*B11/1000000) -> -731.13484 | C22: -
A24: Synthèse
A25: Bénéfices annuels bruts (M$/an) | B25: =B18+B19+B20 -> 31170
A26: Coûts annuels totaux (M$/an) | B26: =B21+B22 -> -4156.1348
A27: Flux net annuel (M$/an) | B27: =B25+B26 -> 27013.865
A28: VAN socio-éco (Mrd $) [hors externalités non monétisées] | B28: =B27/1000*(1-(1+B5)^(-B4))/B5 - B3/1000 -> 396.84821
A31: Note : VAN = Flux_net × [(1-(1+i)^-n)/i] − CAPEX, i = taux actualisation, n = durée de vie.

Sheet VAN
A1: VAN socio-économique -- Yarlung Tsangpo (2025–2074) | L1: Synthèse
A2: Année | B2: Facteur actu. (4,5%) | C2: (-) CAPEX (M$) | D2: (+) Recettes élec. (M$) | E2: (+) Val. CO2 (M$) | F2: (-) Maintenance (M$) | G2: (-) Relocalisation (M$) | H2: Flux net brut (M$) | I2: Flux net actualisé (M$) | J2: VAN cumulée (Mrd $) | L2: Indicateur | M2: Valeur
A3: 2025 | B3: =1/(1+'Flux économiques'!$B$5)^0 -> 1 | C3: =-0.03*'Flux économiques'!$B$3 -> -4110 | D3: 0 | E3: 0 | F3: 0 | G3: 0 | H3: =SUM(C3:G3) -> -4110 | I3: =H3*B3 -> -4110 | J3: =I3/1000 -> -4.11 | L3: VAN-SE (Mrd $) | M3: =SUM(I3:I52)/1000 -> 267.07888
A4: 2026 | B4: =1/(1+'Flux économiques'!$B$5)^1 -> 0.9569378 | C4: =-0.05*'Flux économiques'!$B$3 -> -6850 | D4: 0 | E4: 0 | F4: 0 | G4: 0 | H4: =SUM(C4:G4) -> -6850 | I4: =H4*B4 -> -6555.0239 | J4: =J3+I4/1000 -> -10.665024 | L4: TRI | M4: =IRR(H3:H52) -> 0.13681753
A5: 2027 | B5: =1/(1+'Flux économiques'!$B$5)^2 -> 0.91572995 | C5: =-0.1*'Flux économiques'!$B$3 -> -13700 | D5: 0 | E5: 0 | F5: 0 | G5: 0 | H5: =SUM(C5:G5) -> -13700 | I5: =H5*B5 -> -12545.5 | J5: =J4+I5/1000 -> -23.210524
A6: 2028 | B6: =1/(1+'Flux économiques'!$B$5)^3 -> 0.8762966 | C6: =-0.15*'Flux économiques'!$B$3 -> -20550 | D6: 0 | E6: 0 | F6: 0 | G6: 0 | H6: =SUM(C6:G6) -> -20550 | I6: =H6*B6 -> -18007.895 | J6: =J5+I6/1000 -> -41.218419 | L6: Bilan coûts actualisés (M$) | M6: =SUM(C3:C52)+SUM(F3:F52)+SUM(G3:G52) -> -281581.13
A7: 2029 | B7: =1/(1+'Flux économiques'!$B$5)^4 -> 0.83856134 | C7: =-0.2*'Flux économiques'!$B$3 -> -27400 | D7: 0 | E7: 0 | F7: 0 | G7: 0 | H7: =SUM(C7:G7) -> -27400 | I7: =H7*B7 -> -22976.581 | J7: =J6+I7/1000 -> -64.195 | L7: Bilan bénéfices actualisés (M$) | M7: =SUM(I3:I52)-SUM(C3:C52)-SUM(F3:F52)-SUM(G3:G52) -> 548660.01
A8: 2030 | B8: =1/(1+'Flux économiques'!$B$5)^5 -> 0.80245105 | C8: =-0.22*'Flux économiques'!$B$3 -> -30140 | D8: 0 | E8: 0 | F8: 0 | G8: 0 | H8: =SUM(C8:G8) -> -30140 | I8: =H8*B8 -> -24185.875 | J8: =J7+I8/1000 -> -88.380875
A9: 2031 | B9: =1/(1+'Flux économiques'!$B$5)^6 -> 0.76789574 | C9: =-0.15*'Flux économiques'!$B$3 -> -20550 | D9: 0 | E9: 0 | F9: 0 | G9: 0 | H9: =SUM(C9:G9) -> -20550 | I9: =H9*B9 -> -15780.257 | J9: =J8+I9/1000 -> -104.16113 | L9: VAN / € investi (CAPEX) | M9: =(SUM(I3:I52)/1000)/('Flux économiques'!$B$3/1000) -> 1.9494809
A10: 2032 | B10: =1/(1+'Flux économiques'!$B$5)^7 -> 0.73482846 | C10: =-0.1*'Flux économiques'!$B$3 -> -13700 | D10: 0 | E10: 0 | F10: 0 | G10: 0 | H10: =SUM(C10:G10) -> -13700 | I10: =H10*B10 -> -10067.15 | J10: =J9+I10/1000 -> -114.22828 | L10: Flux net annuel moyen (M$) | M10: =AVERAGE(H3:H52) -> 20551.177
A11: 2033 | B11: =1/(1+'Flux économiques'!$B$5)^8 -> 0.70318513 | C11: 0 | D11: ='Flux économiques'!$B$6*1000000000*'Flux économiques'!$B$7/1000000 -> 28710 | E11: ='Flux économiques'!$B$6*'Flux économiques'!$B$8/1000*'Flux économiques'!$B$9 -> 2460 | F11: =-'Flux économiques'!$B$3*'Flux économiques'!$B$13 -> -3425 | G11: =-'Flux économiques'!$B$10*'Flux économiques'!$B$11/1000000/10 -> -73.113484 | H11: =SUM(C11:G11) -> 27671.887 | I11: =H11*B11 -> 19458.459 | J11: =J10+I11/1000 -> -94.769823
A12: 2034 | B12: =1/(1+'Flux économiques'!$B$5)^9 -> 0.67290443 | C12: 0 | D12: ='Flux économiques'!$B$6*1000000000*'Flux économiques'!$B$7/1000000 -> 28710 | E12: ='Flux économiques'!$B$6*'Flux économiques'!$B$8/1000*'Flux économiques'!$B$9 -> 2460 | F12: =-'Flux économiques'!$B$3*'Flux économiques'!$B$13 -> -3425 | G12: =-'Flux économiques'!$B$10*'Flux économiques'!$B$11/1000000/10 -> -73.113484 | H12: =SUM(C12:G12) -> 27671.887 | I12: =H12*B12 -> 18620.535 | J12: =J11+I12/1000 -> -76.149288
A13: 2035 | B13: =1/(1+'Flux économiques'!$B$5)^10 -> 0.64392768 | C13: 0 | D13: ='Flux économiques'!$B$6*1000000000*'Flux économiques'!$B$7/1000000 -> 28710 | E13: ='Flux économiques'!$B$6*'Flux économiques'!$B$8/1000*'Flux économiques'!$B$9 -> 2460 | F13: =-'Flux économiques'!$B$3*'Flux économiques'!$B$13 -> -3425 | G13: =-'Flux économiques'!$B$10*'Flux économiques'!$B$11/1000000/10 -> -73.113484 | H13: =SUM(C13:G13) -> 27671.887 | I13: =H13*B13 -> 17818.694 | J13: =J12+I13/1000 -> -58.330594
A14: 2036 | B14: =1/(1+'Flux économiques'!$B$5)^11 -> 0.61619874 | C14: 0 | D14: ='Flux économiques'!$B$6*1000000000*'Flux économiques'!$B$7/1000000 -> 28710 | E14: ='Flux économiques'!$B$6*'Flux économiques'!$B$8/1000*'Flux économiques'!$B$9 -> 2460 | F14: =-'Flux économiques'!$B$3*'Flux économiques'!$B$13 -> -3425 | G14: =-'Flux économiques'!$B$10*'Flux économiques'!$B$11/1000000/10 -> -73.113484 | H14: =SUM(C14:G14) -> 27671.887 | I14: =H14*B14 -> 17051.382 | J14: =J13+I14/1000 -> -41.279213
A15: 2037 | B15: =1/(1+'Flux économiques'!$B$5)^12 -> 0.58966386 | C15: 0 | D15: ='Flux économiques'!$B$6*1000000000*'Flux économiques'!$B$7/1000000 -> 28710 | E15: ='Flux économiques'!$B$6*'Flux économiques'!$B$8/1000*'Flux économiques'!$B$9 -> 2460 | F15: =-'Flux économiques'!$B$3*'Flux économiques'!$B$13 -> -3425 | G15: =-'Flux économiques'!$B$10*'Flux économiques'!$B$11/1000000/10 -> -73.113484 | H15: =SUM(C15:G15) -> 27671.887 | I15: =H15*B15 -> 16317.112 | J15: =J14+I15/1000 -> -24.962101
A16: 2038 | B16: =1/(1+'Flux économiques'!$B$5)^13 -> 0.56427164 | C16: 0 | D16: ='Flux économiques'!$B$6*1000000000*'Flux économiques'!$B$7/1000000 -> 28710 | E16: ='Flux économiques'!$B$6*'Flux économiques'!$B$8/1000*'Flux économiques'!$B$9 -> 2460 | F16: =-'Flux économiques'!$B$3*'Flux économiques'!$B$13 -> -3425 | G16: =-'Flux économiques'!$B$10*'Flux économiques'!$B$11/1000000/10 -> -73.113484 | H16: =SUM(C16:G16) -> 27671.887 | I16: =H16*B16 -> 15614.461 | J16: =J15+I16/1000 -> -9.3476404
A17: 2039 | B17: =1/(1+'Flux économiques'!$B$5)^14 -> 0.53997286 | C17: 0 | D17: ='Flux économiques'!$B$6*1000000000*'Flux économiques'!$B$7/1000000 -> 28710 | E17: ='Flux économiques'!$B$6*'Flux économiques'!$B$8/1000*'Flux économiques'!$B$9 -> 2460 | F17: =-'Flux économiques'!$B$3*'Flux économiques'!$B$13 -> -3425 | G17: =-'Flux économiques'!$B$10*'Flux économiques'!$B$11/1000000/10 -> -73.113484 | H17: =SUM(C17:G17) -> 27671.887 | I17: =H17*B17 -> 14942.068 | J17: =J16+I17/1000 -> 5.5944273
A18: 2040 | B18: =1/(1+'Flux économiques'!$B$5)^15 -> 0.51672044 | C18: 0 | D18: ='Flux économiques'!$B$6*1000000000*'Flux économiques'!$B$7/1000000 -> 28710 | E18: ='Flux économiques'!$B$6*'Flux économiques'!$B$8/1000*'Flux économiques'!$B$9 -> 2460 | F18: =-'Flux économiques'!$B$3*'Flux économiques'!$B$13 -> -3425 | G18: =-'Flux économiques'!$B$10*'Flux économiques'!$B$11/1000000/10 -> -73.113484 | H18: =SUM(C18:G18) -> 27671.887 | I18: =H18*B18 -> 14298.629 | J18: =J17+I18/1000 -> 19.893057
A19: 2041 | B19: =1/(1+'Flux économiques'!$B$5)^16 -> 0.49446932 | C19: 0 | D19: ='Flux économiques'!$B$6*1000000000*'Flux économiques'!$B$7/1000000 -> 28710 | E19: ='Flux économiques'!$B$6*'Flux économiques'!$B$8/1000*'Flux économiques'!$B$9 -> 2460 | F19: =-'Flux économiques'!$B$3*'Flux économiques'!$B$13 -> -3425 | G19: =-'Flux économiques'!$B$10*'Flux économiques'!$B$11/1000000/10 -> -73.113484 | H19: =SUM(C19:G19) -> 27671.887 | I19: =H19*B19 -> 13682.899 | J19: =J18+I19/1000 -> 33.575956
A20: 2042 | B20: =1/(1+'Flux économiques'!$B$5)^17 -> 0.47317639 | C20: 0 | D20: ='Flux économiques'!$B$6*1000000000*'Flux économiques'!$B$7/1000000 -> 28710 | E20: ='Flux économiques'!$B$6*'Flux économiques'!$B$8/1000*'Flux économiques'!$B$9 -> 2460 | F20: =-'Flux économiques'!$B$3*'Flux économiques'!$B$13 -> -3425 | G20: =-'Flux économiques'!$B$10*'Flux économiques'!$B$11/1000000/10 -> -73.113484 | H20: =SUM(C20:G20) -> 27671.887 | I20: =H20*B20 -> 13093.683 | J20: =J19+I20/1000 -> 46.669639
A21: 2043 | B21: =1/(1+'Flux économiques'!$B$5)^18 -> 0.45280037 | C21: 0 | D21: ='Flux économiques'!$B$6*1000000000*'Flux économiques'!$B$7/1000000 -> 28710 | E21: ='Flux économiques'!$B$6*'Flux économiques'!$B$8/1000*'Flux économiques'!$B$9 -> 2460 | F21: =-'Flux économiques'!$B$3*'Flux économiques'!$B$13 -> -3425 | G21: 0 | H21: =SUM(C21:G21) -> 27745 | I21: =H21*B21 -> 12562.946 | J21: =J20+I21/1000 -> 59.232585
A22: 2044 | B22: =1/(1+'Flux économiques'!$B$5)^19 -> 0.43330179 | C22: 0 | D22: ='Flux économiques'!$B$6*1000000000*'Flux économiques'!$B$7/1000000 -> 28710 | E22: ='Flux économiques'!$B$6*'Flux économiques'!$B$8/1000*'Flux économiques'!$B$9 -> 2460 | F22: =-'Flux économiques'!$B$3*'Flux économiques'!$B$13 -> -3425 | G22: 0 | H22: =SUM(C22:G22) -> 27745 | I22: =H22*B22 -> 12021.958 | J22: =J21+I22/1000 -> 71.254543
A23: 2045 | B23: =1/(1+'Flux économiques'!$B$5)^20 -> 0.41464286 | C23: 0 | D23: ='Flux économiques'!$B$6*1000000000*'Flux économiques'!$B$7/1000000 -> 28710 | E23: ='Flux économiques'!$B$6*'Flux économiques'!$B$8/1000*'Flux économiques'!$B$9 -> 2460 | F23: =-'Flux économiques'!$B$3*'Flux économiques'!$B$13 -> -3425 | G23: 0 | H23: =SUM(C23:G23) -> 27745 | I23: =H23*B23 -> 11504.266 | J23: =J22+I23/1000 -> 82.758809
A24: 2046 | B24: =1/(1+'Flux économiques'!$B$5)^21 -> 0.39678743 | C24: 0 | D24: ='Flux économiques'!$B$6*1000000000*'Flux économiques'!$B$7/1000000 -> 28710 | E24: ='Flux économiques'!$B$6*'Flux économiques'!$B$8/1000*'Flux économiques'!$B$9 -> 2460 | F24: =-'Flux économiques'!$B$3*'Flux économiques'!$B$13 -> -3425 | G24: 0 | H24: =SUM(C24:G24) -> 27745 | I24: =H24*B24 -> 11008.867 | J24: =J23+I24/1000 -> 93.767677
A25: 2047 | B25: =1/(1+'Flux économiques'!$B$5)^22 -> 0.37970089 | C25: 0 | D25: ='Flux économiques'!$B$6*1000000000*'Flux économiques'!$B$7/1000000 -> 28710 | E25: ='Flux économiques'!$B$6*'Flux économiques'!$B$8/1000*'Flux économiques'!$B$9 -> 2460 | F25: =-'Flux économiques'!$B$3*'Flux économiques'!$B$13 -> -3425 | G25: 0 | H25: =SUM(C25:G25) -> 27745 | I25: =H25*B25 -> 10534.801 | J25: =J24+I25/1000 -> 104.30248
A26: 2048 | B26: =1/(1+'Flux économiques'!$B$5)^23 -> 0.36335013 | C26: 0 | D26: ='Flux économiques'!$B$6*1000000000*'Flux économiques'!$B$7/1000000 -> 28710 | E26: ='Flux économiques'!$B$6*'Flux économiques'!$B$8/1000*'Flux économiques'!$B$9 -> 2460 | F26: =-'Flux économiques'!$B$3*'Flux économiques'!$B$13 -> -3425 | G26: 0 | H26: =SUM(C26:G26) -> 27745 | I26: =H26*B26 -> 10081.149 | J26: =J25+I26/1000 -> 114.38363
A27: 2049 | B27: =1/(1+'Flux économiques'!$B$5)^24 -> 0.34770347 | C27: 0 | D27: ='Flux économiques'!$B$6*1000000000*'Flux économiques'!$B$7/1000000 -> 28710 | E27: ='Flux économiques'!$B$6*'Flux économiques'!$B$8/1000*'Flux économiques'!$B$9 -> 2460 | F27: =-'Flux économiques'!$B$3*'Flux économiques'!$B$13 -> -3425 | G27: 0 | H27: =SUM(C27:G27) -> 27745 | I27: =H27*B27 -> 9647.0329 | J27: =J26+I27/1000 -> 124.03066
A28: 2050 | B28: =1/(1+'Flux économiques'!$B$5)^25 -> 0.3327306 | C28: 0 | D28: ='Flux économiques'!$B$6*1000000000*'Flux économiques'!$B$7/1000000 -> 28710 | E28: ='Flux économiques'!$B$6*'Flux économiques'!$B$8/1000*'Flux économiques'!$B$9 -> 2460 | F28: =-'Flux économiques'!$B$3*'Flux économiques'!$B$13 -> -3425 | G28: 0 | H28: =SUM(C28:G28) -> 27745 | I28: =H28*B28 -> 9231.6104 | J28: =J27+I28/1000 -> 133.26227
A29: 2051 | B29: =1/(1+'Flux économiques'!$B$5)^26 -> 0.31840248 | C29: 0 | D29: ='Flux économiques'!$B$6*1000000000*'Flux économiques'!$B$7/1000000 -> 28710 | E29: ='Flux économiques'!$B$6*'Flux économiques'!$B$8/1000*'Flux économiques'!$B$9 -> 2460 | F29: =-'Flux économiques'!$B$3*'Flux économiques'!$B$13 -> -3425 | G29: 0 | H29: =SUM(C29:G29) -> 27745 | I29: =H29*B29 -> 8834.0769 | J29: =J28+I29/1000 -> 142.09635
A30: 2052 | B30: =1/(1+'Flux économiques'!$B$5)^27 -> 0.30469137 | C30: 0 | D30: ='Flux économiques'!$B$6*1000000000*'Flux économiques'!$B$7/1000000 -> 28710 | E30: ='Flux économiques'!$B$6*'Flux économiques'!$B$8/1000*'Flux économiques'!$B$9 -> 2460 | F30: =-'Flux économiques'!$B$3*'Flux économiques'!$B$13 -> -3425 | G30: 0 | H30: =SUM(C30:G30) -> 27745 | I30: =H30*B30 -> 8453.6621 | J30: =J29+I30/1000 -> 150.55001
A31: 2053 | B31: =1/(1+'Flux économiques'!$B$5)^28 -> 0.29157069 | C31: 0 | D31: ='Flux économiques'!$B$6*1000000000*'Flux économiques'!$B$7/1000000 -> 28710 | E31: ='Flux économiques'!$B$6*'Flux économiques'!$B$8/1000*'Flux économiques'!$B$9 -> 2460 | F31: =-'Flux économiques'!$B$3*'Flux économiques'!$B$13 -> -3425 | G31: 0 | H31: =SUM(C31:G31) -> 27745 | I31: =H31*B31 -> 8089.6288 | J31: =J30+I31/1000 -> 158.63964
A32: 2054 | B32: =1/(1+'Flux économiques'!$B$5)^29 -> 0.27901502 | C32: 0 | D32: ='Flux économiques'!$B$6*1000000000*'Flux économiques'!$B$7/1000000 -> 28710 | E32: ='Flux économiques'!$B$6*'Flux économiques'!$B$8/1000*'Flux économiques'!$B$9 -> 2460 | F32: =-'Flux économiques'!$B$3*'Flux économiques'!$B$13 -> -3425 | G32: 0 | H32: =SUM(C32:G32) -> 27745 | I32: =H32*B32 -> 7741.2716 | J32: =J31+I32/1000 -> 166.38091
A33: 2055 | B33: =1/(1+'Flux économiques'!$B$5)^30 -> 0.26700002 | C33: 0 | D33: ='Flux économiques'!$B$6*1000000000*'Flux économiques'!$B$7/1000000 -> 28710 | E33: ='Flux économiques'!$B$6*'Flux économiques'!$B$8/1000*'Flux économiques'!$B$9 -> 2460 | F33: =-'Flux économiques'!$B$3*'Flux économiques'!$B$13 -> -3425 | G33: 0 | H33: =SUM(C33:G33) -> 27745 | I33: =H33*B33 -> 7407.9154 | J33: =J32+I33/1000 -> 173.78883
A34: 2056 | B34: =1/(1+'Flux économiques'!$B$5)^31 -> 0.25550241 | C34: 0 | D34: ='Flux économiques'!$B$6*1000000000*'Flux économiques'!$B$7/1000000 -> 28710 | E34: ='Flux économiques'!$B$6*'Flux économiques'!$B$8/1000*'Flux économiques'!$B$9 -> 2460 | F34: =-'Flux économiques'!$B$3*'Flux économiques'!$B$13 -> -3425 | G34: 0 | H34: =SUM(C34:G34) -> 27745 | I34: =H34*B34 -> 7088.9143 | J34: =J33+I34/1000 -> 180.87774
A35: 2057 | B35: =1/(1+'Flux économiques'!$B$5)^32 -> 0.24449991 | C35: 0 | D35: ='Flux économiques'!$B$6*1000000000*'Flux économiques'!$B$7/1000000 -> 28710 | E35: ='Flux économiques'!$B$6*'Flux économiques'!$B$8/1000*'Flux économiques'!$B$9 -> 2460 | F35: =-'Flux économiques'!$B$3*'Flux économiques'!$B$13 -> -3425 | G35: 0 | H35: =SUM(C35:G35) -> 27745 | I35: =H35*B35 -> 6783.65 | J35: =J34+I35/1000 -> 187.66139
A36: 2058 | B36: =1/(1+'Flux économiques'!$B$5)^33 -> 0.23397121 | C36: 0 | D36: ='Flux économiques'!$B$6*1000000000*'Flux économiques'!$B$7/1000000 -> 28710 | E36: ='Flux économiques'!$B$6*'Flux économiques'!$B$8/1000*'Flux économiques'!$B$9 -> 2460 | F36: =-'Flux économiques'!$B$3*'Flux économiques'!$B$13 -> -3425 | G36: 0 | H36: =SUM(C36:G36) -> 27745 | I36: =H36*B36 -> 6491.5311 | J36: =J35+I36/1000 -> 194.15292
A37: 2059 | B37: =1/(1+'Flux économiques'!$B$5)^34 -> 0.22389589 | C37: 0 | D37: ='Flux économiques'!$B$6*1000000000*'Flux économiques'!$B$7/1000000 -> 28710 | E37: ='Flux économiques'!$B$6*'Flux économiques'!$B$8/1000*'Flux économiques'!$B$9 -> 2460 | F37: =-'Flux économiques'!$B$3*'Flux économiques'!$B$13 -> -3425 | G37: 0 | H37: =SUM(C37:G37) -> 27745 | I37: =H37*B37 -> 6211.9915 | J37: =J36+I37/1000 -> 200.36491
A38: 2060 | B38: =1/(1+'Flux économiques'!$B$5)^35 -> 0.21425444 | C38: 0 | D38: ='Flux économiques'!$B$6*1000000000*'Flux économiques'!$B$7/1000000 -> 28710 | E38: ='Flux économiques'!$B$6*'Flux économiques'!$B$8/1000*'Flux économiques'!$B$9 -> 2460 | F38: =-'Flux économiques'!$B$3*'Flux économiques'!$B$13 -> -3425 | G38: 0 | H38: =SUM(C38:G38) -> 27745 | I38: =H38*B38 -> 5944.4895 | J38: =J37+I38/1000 -> 206.3094
A39: 2061 | B39: =1/(1+'Flux économiques'!$B$5)^36 -> 0.20502817 | C39: 0 | D39: ='Flux économiques'!$B$6*1000000000*'Flux économiques'!$B$7/1000000 -> 28710 | E39: ='Flux économiques'!$B$6*'Flux économiques'!$B$8/1000*'Flux économiques'!$B$9 -> 2460 | F39: =-'Flux économiques'!$B$3*'Flux économiques'!$B$13 -> -3425 | G39: 0 | H39: =SUM(C39:G39) -> 27745 | I39: =H39*B39 -> 5688.5067 | J39: =J38+I39/1000 -> 211.99791
A40: 2062 | B40: =1/(1+'Flux économiques'!$B$5)^37 -> 0.19619921 | C40: 0 | D40: ='Flux économiques'!$B$6*1000000000*'Flux économiques'!$B$7/1000000 -> 28710 | E40: ='Flux économiques'!$B$6*'Flux économiques'!$B$8/1000*'Flux économiques'!$B$9 -> 2460 | F40: =-'Flux économiques'!$B$3*'Flux économiques'!$B$13 -> -3425 | G40: 0 | H40: =SUM(C40:G40) -> 27745 | I40: =H40*B40 -> 5443.5471 | J40: =J39+I40/1000 -> 217.44146
...

Sheet Stress test
A1: Impacts sur la VAN-SE de scénarii de stress (Mrd $)
A2: Facteur rente exploitation (calculé) | B2: =((1-(1+'Flux économiques'!$B$5)^(-44))/'Flux économiques'!$B$5)/(1+'Flux économiques'!$B$5)^6 -> 14.604135
B3: Benchmark | C3: CAPEX +10% | D3: Maintenance +10% | E3: Total coûts +10% | F3: Production –10% | G3: Prix élec. –10% | H3: Production +10% | I3: Prix élec. +10% | J3: Prix CO2 +10%
A4: Choc | C4: CAPEX +10% | D4: Maint. +10% | E4: Coûts +10% | F4: Prod. -10% | G4: Prix -10% | H4: Prod. +10% | I4: Prix élec. +10% | J4: Prix CO2+10%
A5: VAN-SE (Mrd $) | B5: =VAN!J52 -> 267.07888 | C5: =VAN!J52+(-0.1*'Flux économiques'!$B$3/1000) -> 253.37888 | D5: =VAN!J52+(-0.1*'Flux économiques'!$B$3*'Flux économiques'!$B$13*B2/1000) -> 262.07696 | E5: =VAN!J52+(-0.1*('Flux économiques'!$B$3/1000+'Flux économiques'!$B$3*'Flux économiques'!$B$13*B2/1000)) -> 248.37696 | F5: =VAN!J52+(-0.1*('Flux économiques'!$B$6*1000000000*'Flux économiques'!$B$7/1000000+'Flux économiques'!$B$6*'Flux économiques'!$B$8/1000*'Flux économiques'!$B$9)*B2/1000) -> 221.55779 | G5: =VAN!J52+(-0.1*'Flux économiques'!$B$6*1000000000*'Flux économiques'!$B$7/1000000*B2/1000) -> 225.15041 | H5: =VAN!J52+(0.1*('Flux économiques'!$B$6*1000000000*'Flux économiques'!$B$7/1000000+'Flux économiques'!$B$6*'Flux économiques'!$B$8/1000*'Flux économiques'!$B$9)*B2/1000) -> 312.59997 | I5: =VAN!J52+(0.1*'Flux économiques'!$B$6*1000000000*'Flux économiques'!$B$7/1000000*B2/1000) -> 309.00735 | J5: =VAN!J52+(0.1*'Flux économiques'!$B$6*'Flux économiques'!$B$8/1000*'Flux économiques'!$B$9*B2/1000) -> 270.6715
A6: Delta valeur (Mrd $) | C6: =-0.1*'Flux économiques'!$B$3/1000 -> -13.7 | D6: =-0.1*'Flux économiques'!$B$3*'Flux économiques'!$B$13*B2/1000 -> -5.0019163 | E6: =-0.1*('Flux économiques'!$B$3/1000+'Flux économiques'!$B$3*'Flux économiques'!$B$13*B2/1000) -> -18.701916 | F6: =-0.1*('Flux économiques'!$B$6*1000000000*'Flux économiques'!$B$7/1000000+'Flux économiques'!$B$6*'Flux économiques'!$B$8/1000*'Flux économiques'!$B$9)*B2/1000 -> -45.52109 | G6: =-0.1*'Flux économiques'!$B$6*1000000000*'Flux économiques'!$B$7/1000000*B2/1000 -> -41.928472 | H6: =0.1*('Flux économiques'!$B$6*1000000000*'Flux économiques'!$B$7/1000000+'Flux économiques'!$B$6*'Flux économiques'!$B$8/1000*'Flux économiques'!$B$9)*B2/1000 -> 45.52109 | I6: =0.1*'Flux économiques'!$B$6*1000000000*'Flux économiques'!$B$7/1000000*B2/1000 -> 41.928472 | J6: =0.1*'Flux économiques'!$B$6*'Flux économiques'!$B$8/1000*'Flux économiques'!$B$9*B2/1000 -> 3.5926173
A7: Taux d'impact (%) | C7: =(-0.1*'Flux économiques'!$B$3/1000)/VAN!J52 -> -0.051295707 | D7: =(-0.1*'Flux économiques'!$B$3*'Flux économiques'!$B$13*B2/1000)/VAN!J52 -> -0.018728236 | E7: =(-0.1*('Flux économiques'!$B$3/1000+'Flux économiques'!$B$3*'Flux économiques'!$B$13*B2/1000))/VAN!J52 -> -0.070023943 | F7: =(-0.1*('Flux économiques'!$B$6*1000000000*'Flux économiques'!$B$7/1000000+'Flux économiques'!$B$6*'Flux économiques'!$B$8/1000*'Flux économiques'!$B$9)*B2/1000)/VAN!J52 -> -0.17044062 | G7: =(-0.1*'Flux économiques'!$B$6*1000000000*'Flux économiques'!$B$7/1000000*B2/1000)/VAN!J52 -> -0.1569891 | H7: =(0.1*('Flux économiques'!$B$6*1000000000*'Flux économiques'!$B$7/1000000+'Flux économiques'!$B$6*'Flux économiques'!$B$8/1000*'Flux économiques'!$B$9)*B2/1000)/VAN!J52 -> 0.17044062 | I7: =(0.1*'Flux économiques'!$B$6*1000000000*'Flux économiques'!$B$7/1000000*B2/1000)/VAN!J52 -> 0.1569891 | J7: =(0.1*'Flux économiques'!$B$6*'Flux économiques'!$B$8/1000*'Flux économiques'!$B$9*B2/1000)/VAN!J52 -> 0.013451521
